Workbook
Name Members: Settings!$A$16:$A$25
Name Statuses: Settings!$F$7:$F$16
Name Priorities: Settings!$G$7:$G$16
Name ProgressVals: Settings!$H$7:$H$16
Name LearnStatus: Settings!$I$7:$I$16
Name RiskStatus: Settings!$J$7:$J$16
Name Moods: Settings!$K$7:$K$16
Name ProjStart: Settings!$B$8
Name ProjEnd: Settings!$B$9
Name Milestones: Milestones!$B$6:$B$35

Sheet Start Here
B2: Project Tracker
B3: =Settings!B6
B4: Tasks · timeline · milestones · daily check-ins · learning · risks, all in one workbook.
B6: Go to
B7: ▸ Dashboard | C7: Live overview: KPIs, project health, member focus picker, deadlines and charts.
B8: ▸ Tasks | C8: Your to-do list. One row per task with owner, status, priority, dates and progress.
B9: ▸ Timeline | C9: Gantt chart built automatically from the Tasks sheet. Change the start date to scroll.
B10: ▸ Milestones | C10: Big checkpoints. % done is calculated from the tasks linked to each one.
B11: ▸ Check-ins | C11: Daily stand-up log: what I did, what's next, what's blocking me, and my mood.
B12: ▸ Learning | C12: Skills matrix: every member tracks the topics they're learning.
B13: ▸ Risks & Issues | C13: What could go wrong, how bad it is (score), who owns it, and the plan.
B14: ▸ Settings | C14: Project name, dates, time zone, team members and drop-down lists.
B16: Set up in 3 steps
B17: 1 · Settings: type your project name, start and end dates, time zone and team members.
B18: 2 · Milestones: list your big checkpoints. Then add tasks on the Tasks sheet and link each one to a milestone.
B19: 3 · Every day: update task status and progress, and add a short row on Check-ins. The Dashboard does the rest.
B21: Colour key
B22: Blue text | C22: Cells you type in (inputs).
B23: Grey cells | C23: Calculated by formulas: don't type here.
B24: Purple italics | C24: Example rows: overwrite or delete them.
B25: Red | C25: Overdue, blocked or high risk: needs attention.
B27: Tips
B28: • Use the filter arrows on each header row to see only your own tasks, or only open ones.
B29: • Share the workbook through OneDrive, SharePoint or Google Drive so everyone edits the same copy.
B30: • The Dashboard is protected so its formulas can't be broken by accident (Review → Unprotect Sheet, no password).
B31: • All dates and times are shown in the time zone set on the Settings sheet (currently: Local time), 12-hour AM/PM.
B32: • Need more rows? Tasks has 300, Check-ins 500, Learning 150 and Risks 100 ready to use.

Sheet Dashboard
A1: =Settings!B6&" · Project Dashboard"
A2: ="Lead: "&Settings!B7&" · "&TEXT(ProjStart,"mmm d, yyyy")&" → "&TEXT(ProjEnd,"mmm d, yyyy h:mm AM/PM")&" · Times: "&Settings!B10
A3: ="Updated "&TEXT(NOW(),"ddd, mmm d yyyy, h:mm AM/PM")&" · All numbers are formulas: edit the other sheets, not this one."
A5: Tasks | D5: Done | G5: % complete | J5: Avg. progress | M5: Days to deadline
A6: =COUNTA(Tasks!$B$6:$B$305) | D6: =COUNTIF(Tasks!$E$6:$E$305,"Done") | G6: =IFERROR(COUNTIF(Tasks!$E$6:$E$305,"Done")/COUNTA(Tasks!$B$6:$B$305),0) | J6: =IFERROR(SUMPRODUCT((Tasks!$B$6:$B$305<>"")*Tasks!$K$6:$K$305)/COUNTA(Tasks!$B$6:$B$305),0) | M6: =IF(ProjEnd="","—",MAX(0,ROUNDDOWN(ProjEnd-NOW(),0)))
A8: Overdue | D8: Due in 7 days | G8: Blocked | J8: Unassigned (open) | M8: High risks open
A9: =COUNTIF(Tasks!$M$6:$M$305,"Overdue") | D9: =SUMPRODUCT((Tasks!$B$6:$B$305<>"")*(Tasks!$E$6:$E$305<>"Done")*(Tasks!$H$6:$H$305>=NOW())*(Tasks!$H$6:$H$305<NOW()+7)) | G9: =COUNTIF(Tasks!$E$6:$E$305,"Blocked") | J9: =SUMPRODUCT((Tasks!$B$6:$B$305<>"")*(Tasks!$E$6:$E$305<>"Done")*(Tasks!$D$6:$D$305="")) | M9: =COUNTIFS('Risks & Issues'!$G$6:$G$105,"High",'Risks & Issues'!$J$6:$J$105,"<>Closed")
A11: Project health
A12: Time elapsed | B12: =IFERROR(MAX(0,MIN(1,(NOW()-ProjStart)/(ProjEnd-ProjStart))),0) | D12: =IF(A9+G9>0,"AT RISK",IF(B13+0.15<B12,"BEHIND SCHEDULE","ON TRACK")) | J12: Rule: at risk if anything is overdue or blocked; behind if work done trails time elapsed by more than 15 points.
A13: Work complete | B13: =G6
A15: Member focus | G15: Next deadlines (open tasks)
A16: Pick a member ▸ | B16: Alex (example) | G16: Due | H16: Task | K16: Owner | L16: Status
A17: Open tasks | B17: =COUNTIFS(Tasks!$D$6:$D$305,$B$16,Tasks!$E$6:$E$305,"<>Done") | G17: =IFERROR(INDEX(Tasks!$H$6:$H$305,MATCH(SMALL(Tasks!$P$6:$P$305,1),Tasks!$P$6:$P$305,0)),"") | H17: =IFERROR(INDEX(Tasks!$B$6:$B$305,MATCH(SMALL(Tasks!$P$6:$P$305,1),Tasks!$P$6:$P$305,0)),"") | K17: =IFERROR(IF(INDEX(Tasks!$D$6:$D$305,MATCH(SMALL(Tasks!$P$6:$P$305,1),Tasks!$P$6:$P$305,0))="","(unassigned)",INDEX(Tasks!$D$6:$D$305,MATCH(SMALL(Tasks!$P$6:$P$305,1),Tasks!$P$6:$P$305,0))),"") | L17: =IFERROR(INDEX(Tasks!$E$6:$E$305,MATCH(SMALL(Tasks!$P$6:$P$305,1),Tasks!$P$6:$P$305,0)),"")
A18: Done | B18: =COUNTIFS(Tasks!$D$6:$D$305,$B$16,Tasks!$E$6:$E$305,"Done") | G18: =IFERROR(INDEX(Tasks!$H$6:$H$305,MATCH(SMALL(Tasks!$P$6:$P$305,2),Tasks!$P$6:$P$305,0)),"") | H18: =IFERROR(INDEX(Tasks!$B$6:$B$305,MATCH(SMALL(Tasks!$P$6:$P$305,2),Tasks!$P$6:$P$305,0)),"") | K18: =IFERROR(IF(INDEX(Tasks!$D$6:$D$305,MATCH(SMALL(Tasks!$P$6:$P$305,2),Tasks!$P$6:$P$305,0))="","(unassigned)",INDEX(Tasks!$D$6:$D$305,MATCH(SMALL(Tasks!$P$6:$P$305,2),Tasks!$P$6:$P$305,0))),"") | L18: =IFERROR(INDEX(Tasks!$E$6:$E$305,MATCH(SMALL(Tasks!$P$6:$P$305,2),Tasks!$P$6:$P$305,0)),"")
A19: Overdue | B19: =COUNTIFS(Tasks!$D$6:$D$305,$B$16,Tasks!$M$6:$M$305,"Overdue") | G19: =IFERROR(INDEX(Tasks!$H$6:$H$305,MATCH(SMALL(Tasks!$P$6:$P$305,3),Tasks!$P$6:$P$305,0)),"") | H19: =IFERROR(INDEX(Tasks!$B$6:$B$305,MATCH(SMALL(Tasks!$P$6:$P$305,3),Tasks!$P$6:$P$305,0)),"") | K19: =IFERROR(IF(INDEX(Tasks!$D$6:$D$305,MATCH(SMALL(Tasks!$P$6:$P$305,3),Tasks!$P$6:$P$305,0))="","(unassigned)",INDEX(Tasks!$D$6:$D$305,MATCH(SMALL(Tasks!$P$6:$P$305,3),Tasks!$P$6:$P$305,0))),"") | L19: =IFERROR(INDEX(Tasks!$E$6:$E$305,MATCH(SMALL(Tasks!$P$6:$P$305,3),Tasks!$P$6:$P$305,0)),"")
A20: Open hours (est.) | B20: =SUMIFS(Tasks!$J$6:$J$305,Tasks!$D$6:$D$305,$B$16,Tasks!$E$6:$E$305,"<>Done") | G20: =IFERROR(INDEX(Tasks!$H$6:$H$305,MATCH(SMALL(Tasks!$P$6:$P$305,4),Tasks!$P$6:$P$305,0)),"") | H20: =IFERROR(INDEX(Tasks!$B$6:$B$305,MATCH(SMALL(Tasks!$P$6:$P$305,4),Tasks!$P$6:$P$305,0)),"") | K20: =IFERROR(IF(INDEX(Tasks!$D$6:$D$305,MATCH(SMALL(Tasks!$P$6:$P$305,4),Tasks!$P$6:$P$305,0))="","(unassigned)",INDEX(Tasks!$D$6:$D$305,MATCH(SMALL(Tasks!$P$6:$P$305,4),Tasks!$P$6:$P$305,0))),"") | L20: =IFERROR(INDEX(Tasks!$E$6:$E$305,MATCH(SMALL(Tasks!$P$6:$P$305,4),Tasks!$P$6:$P$305,0)),"")
A21: Next due | B21: =IF(SUMPRODUCT(MIN(Tasks!$H$6:$H$305+((Tasks!$D$6:$D$305<>$B$16)+(Tasks!$E$6:$E$305="Done")+(Tasks!$H$6:$H$305=""))*1000000))>100000,"—",SUMPRODUCT(MIN(Tasks!$H$6:$H$305+((Tasks!$D$6:$D$305<>$B$16)+(Tasks!$E$6:$E$305="Done")+(Tasks!$H$6:$H$305=""))*1000000))) | G21: =IFERROR(INDEX(Tasks!$H$6:$H$305,MATCH(SMALL(Tasks!$P$6:$P$305,5),Tasks!$P$6:$P$305,0)),"") | H21: =IFERROR(INDEX(Tasks!$B$6:$B$305,MATCH(SMALL(Tasks!$P$6:$P$305,5),Tasks!$P$6:$P$305,0)),"") | K21: =IFERROR(IF(INDEX(Tasks!$D$6:$D$305,MATCH(SMALL(Tasks!$P$6:$P$305,5),Tasks!$P$6:$P$305,0))="","(unassigned)",INDEX(Tasks!$D$6:$D$305,MATCH(SMALL(Tasks!$P$6:$P$305,5),Tasks!$P$6:$P$305,0))),"") | L21: =IFERROR(INDEX(Tasks!$E$6:$E$305,MATCH(SMALL(Tasks!$P$6:$P$305,5),Tasks!$P$6:$P$305,0)),"")
A22: Next task | B22: =IF(SUMPRODUCT(MIN(Tasks!$H$6:$H$305+((Tasks!$D$6:$D$305<>$B$16)+(Tasks!$E$6:$E$305="Done")+(Tasks!$H$6:$H$305=""))*1000000))>100000,"—",INDEX(Tasks!$B:$B,SUMPRODUCT(MAX((Tasks!$D$6:$D$305=$B$16)*(Tasks!$E$6:$E$305<>"Done")*(Tasks!$H$6:$H$305=SUMPRODUCT(MIN(Tasks!$H$6:$H$305+((Tasks!$D$6:$D$305<>$B$16)+(Tasks!$E$6:$E$305="Done")+(Tasks!$H$6:$H$305=""))*1000000)))*ROW(Tasks!$H$6:$H$305))))) | G22: =IFERROR(INDEX(Tasks!$H$6:$H$305,MATCH(SMALL(Tasks!$P$6:$P$305,6),Tasks!$P$6:$P$305,0)),"") | H22: =IFERROR(INDEX(Tasks!$B$6:$B$305,MATCH(SMALL(Tasks!$P$6:$P$305,6),Tasks!$P$6:$P$305,0)),"") | K22: =IFERROR(IF(INDEX(Tasks!$D$6:$D$305,MATCH(SMALL(Tasks!$P$6:$P$305,6),Tasks!$P$6:$P$305,0))="","(unassigned)",INDEX(Tasks!$D$6:$D$305,MATCH(SMALL(Tasks!$P$6:$P$305,6),Tasks!$P$6:$P$305,0))),"") | L22: =IFERROR(INDEX(Tasks!$E$6:$E$305,MATCH(SMALL(Tasks!$P$6:$P$305,6),Tasks!$P$6:$P$305,0)),"")
A23: Last check-in | B23: =IF(COUNTIF('Check-ins'!$B$6:$B$505,$B$16)=0,"—",SUMPRODUCT(MAX(('Check-ins'!$B$6:$B$505=$B$16)*'Check-ins'!$A$6:$A$505))) | G23: =IFERROR(INDEX(Tasks!$H$6:$H$305,MATCH(SMALL(Tasks!$P$6:$P$305,7),Tasks!$P$6:$P$305,0)),"") | H23: =IFERROR(INDEX(Tasks!$B$6:$B$305,MATCH(SMALL(Tasks!$P$6:$P$305,7),Tasks!$P$6:$P$305,0)),"") | K23: =IFERROR(IF(INDEX(Tasks!$D$6:$D$305,MATCH(SMALL(Tasks!$P$6:$P$305,7),Tasks!$P$6:$P$305,0))="","(unassigned)",INDEX(Tasks!$D$6:$D$305,MATCH(SMALL(Tasks!$P$6:$P$305,7),Tasks!$P$6:$P$305,0))),"") | L23: =IFERROR(INDEX(Tasks!$E$6:$E$305,MATCH(SMALL(Tasks!$P$6:$P$305,7),Tasks!$P$6:$P$305,0)),"")
A24: Learning done | B24: =IFERROR(INDEX(Learning!$H$7:$Q$7,MATCH($B$16,Learning!$H$5:$Q$5,0)),0) | G24: =IFERROR(INDEX(Tasks!$H$6:$H$305,MATCH(SMALL(Tasks!$P$6:$P$305,8),Tasks!$P$6:$P$305,0)),"") | H24: =IFERROR(INDEX(Tasks!$B$6:$B$305,MATCH(SMALL(Tasks!$P$6:$P$305,8),Tasks!$P$6:$P$305,0)),"") | K24: =IFERROR(IF(INDEX(Tasks!$D$6:$D$305,MATCH(SMALL(Tasks!$P$6:$P$305,8),Tasks!$P$6:$P$305,0))="","(unassigned)",INDEX(Tasks!$D$6:$D$305,MATCH(SMALL(Tasks!$P$6:$P$305,8),Tasks!$P$6:$P$305,0))),"") | L24: =IFERROR(INDEX(Tasks!$E$6:$E$305,MATCH(SMALL(Tasks!$P$6:$P$305,8),Tasks!$P$6:$P$305,0)),"")
A27: Tasks by status | D27: Open tasks by priority
A28: Status | B28: Tasks | D28: Priority | E28: Open
A29: =INDEX(Statuses,1) | B29: =COUNTIF(Tasks!$E$6:$E$305,A29) | D29: =INDEX(Priorities,1) | E29: =COUNTIFS(Tasks!$F$6:$F$305,D29,Tasks!$E$6:$E$305,"<>Done")
A30: =INDEX(Statuses,2) | B30: =COUNTIF(Tasks!$E$6:$E$305,A30) | D30: =INDEX(Priorities,2) | E30: =COUNTIFS(Tasks!$F$6:$F$305,D30,Tasks!$E$6:$E$305,"<>Done")
A31: =INDEX(Statuses,3) | B31: =COUNTIF(Tasks!$E$6:$E$305,A31) | D31: =INDEX(Priorities,3) | E31: =COUNTIFS(Tasks!$F$6:$F$305,D31,Tasks!$E$6:$E$305,"<>Done")
A32: =INDEX(Statuses,4) | B32: =COUNTIF(Tasks!$E$6:$E$305,A32) | D32: =INDEX(Priorities,4) | E32: =COUNTIFS(Tasks!$F$6:$F$305,D32,Tasks!$E$6:$E$305,"<>Done")
A33: =INDEX(Statuses,5) | B33: =COUNTIF(Tasks!$E$6:$E$305,A33)
A46: Team workload & engagement | I46: Weekly progress (burn-up)
A47: Member | B47: Open | C47: Done | D47: Overdue | E47: Hours open | F47: Check-ins (7d) | G47: Learning % | J47: Week of | K47: Completed | L47: Cumulative | M47: Total tasks
A48: =IF(INDEX(Members,1)="","",INDEX(Members,1)) | B48: =IF(A48="","",COUNTIFS(Tasks!$D$6:$D$305,A48,Tasks!$E$6:$E$305,"<>Done")) | C48: =IF(A48="","",COUNTIFS(Tasks!$D$6:$D$305,A48,Tasks!$E$6:$E$305,"Done")) | D48: =IF(A48="","",COUNTIFS(Tasks!$D$6:$D$305,A48,Tasks!$M$6:$M$305,"Overdue")) | E48: =IF(A48="","",SUMIFS(Tasks!$J$6:$J$305,Tasks!$D$6:$D$305,A48,Tasks!$E$6:$E$305,"<>Done")) | F48: =IF(A48="","",COUNTIFS('Check-ins'!$B$6:$B$505,A48,'Check-ins'!$A$6:$A$505,">="&(TODAY()-6))) | G48: =IF(A48="","",IFERROR(INDEX(Learning!$H$7:$Q$7,MATCH(A48,Learning!$H$5:$Q$5,0)),0)) | J48: =INT(ProjStart)+7*0 | K48: =COUNTIFS(Tasks!$I$6:$I$305,">="&J48,Tasks!$I$6:$I$305,"<"&(J48+7)) | L48: =IF(J48>TODAY(),NA(),COUNTIFS(Tasks!$I$6:$I$305,"<"&(J48+7),Tasks!$E$6:$E$305,"Done")) | M48: =COUNTA(Tasks!$B$6:$B$305)
A49: =IF(INDEX(Members,2)="","",INDEX(Members,2)) | B49: =IF(A49="","",COUNTIFS(Tasks!$D$6:$D$305,A49,Tasks!$E$6:$E$305,"<>Done")) | C49: =IF(A49="","",COUNTIFS(Tasks!$D$6:$D$305,A49,Tasks!$E$6:$E$305,"Done")) | D49: =IF(A49="","",COUNTIFS(Tasks!$D$6:$D$305,A49,Tasks!$M$6:$M$305,"Overdue")) | E49: =IF(A49="","",SUMIFS(Tasks!$J$6:$J$305,Tasks!$D$6:$D$305,A49,Tasks!$E$6:$E$305,"<>Done")) | F49: =IF(A49="","",COUNTIFS('Check-ins'!$B$6:$B$505,A49,'Check-ins'!$A$6:$A$505,">="&(TODAY()-6))) | G49: =IF(A49="","",IFERROR(INDEX(Learning!$H$7:$Q$7,MATCH(A49,Learning!$H$5:$Q$5,0)),0)) | J49: =INT(ProjStart)+7*1 | K49: =COUNTIFS(Tasks!$I$6:$I$305,">="&J49,Tasks!$I$6:$I$305,"<"&(J49+7)) | L49: =IF(J49>TODAY(),NA(),COUNTIFS(Tasks!$I$6:$I$305,"<"&(J49+7),Tasks!$E$6:$E$305,"Done")) | M49: =COUNTA(Tasks!$B$6:$B$305)
A50: =IF(INDEX(Members,3)="","",INDEX(Members,3)) | B50: =IF(A50="","",COUNTIFS(Tasks!$D$6:$D$305,A50,Tasks!$E$6:$E$305,"<>Done")) | C50: =IF(A50="","",COUNTIFS(Tasks!$D$6:$D$305,A50,Tasks!$E$6:$E$305,"Done")) | D50: =IF(A50="","",COUNTIFS(Tasks!$D$6:$D$305,A50,Tasks!$M$6:$M$305,"Overdue")) | E50: =IF(A50="","",SUMIFS(Tasks!$J$6:$J$305,Tasks!$D$6:$D$305,A50,Tasks!$E$6:$E$305,"<>Done")) | F50: =IF(A50="","",COUNTIFS('Check-ins'!$B$6:$B$505,A50,'Check-ins'!$A$6:$A$505,">="&(TODAY()-6))) | G50: =IF(A50="","",IFERROR(INDEX(Learning!$H$7:$Q$7,MATCH(A50,Learning!$H$5:$Q$5,0)),0)) | J50: =INT(ProjStart)+7*2 | K50: =COUNTIFS(Tasks!$I$6:$I$305,">="&J50,Tasks!$I$6:$I$305,"<"&(J50+7)) | L50: =IF(J50>TODAY(),NA(),COUNTIFS(Tasks!$I$6:$I$305,"<"&(J50+7),Tasks!$E$6:$E$305,"Done")) | M50: =COUNTA(Tasks!$B$6:$B$305)
A51: =IF(INDEX(Members,4)="","",INDEX(Members,4)) | B51: =IF(A51="","",COUNTIFS(Tasks!$D$6:$D$305,A51,Tasks!$E$6:$E$305,"<>Done")) | C51: =IF(A51="","",COUNTIFS(Tasks!$D$6:$D$305,A51,Tasks!$E$6:$E$305,"Done")) | D51: =IF(A51="","",COUNTIFS(Tasks!$D$6:$D$305,A51,Tasks!$M$6:$M$305,"Overdue")) | E51: =IF(A51="","",SUMIFS(Tasks!$J$6:$J$305,Tasks!$D$6:$D$305,A51,Tasks!$E$6:$E$305,"<>Done")) | F51: =IF(A51="","",COUNTIFS('Check-ins'!$B$6:$B$505,A51,'Check-ins'!$A$6:$A$505,">="&(TODAY()-6))) | G51: =IF(A51="","",IFERROR(INDEX(Learning!$H$7:$Q$7,MATCH(A51,Learning!$H$5:$Q$5,0)),0)) | J51: =INT(ProjStart)+7*3 | K51: =COUNTIFS(Tasks!$I$6:$I$305,">="&J51,Tasks!$I$6:$I$305,"<"&(J51+7)) | L51: =IF(J51>TODAY(),NA(),COUNTIFS(Tasks!$I$6:$I$305,"<"&(J51+7),Tasks!$E$6:$E$305,"Done")) | M51: =COUNTA(Tasks!$B$6:$B$305)
A52: =IF(INDEX(Members,5)="","",INDEX(Members,5)) | B52: =IF(A52="","",COUNTIFS(Tasks!$D$6:$D$305,A52,Tasks!$E$6:$E$305,"<>Done")) | C52: =IF(A52="","",COUNTIFS(Tasks!$D$6:$D$305,A52,Tasks!$E$6:$E$305,"Done")) | D52: =IF(A52="","",COUNTIFS(Tasks!$D$6:$D$305,A52,Tasks!$M$6:$M$305,"Overdue")) | E52: =IF(A52="","",SUMIFS(Tasks!$J$6:$J$305,Tasks!$D$6:$D$305,A52,Tasks!$E$6:$E$305,"<>Done")) | F52: =IF(A52="","",COUNTIFS('Check-ins'!$B$6:$B$505,A52,'Check-ins'!$A$6:$A$505,">="&(TODAY()-6))) | G52: =IF(A52="","",IFERROR(INDEX(Learning!$H$7:$Q$7,MATCH(A52,Learning!$H$5:$Q$5,0)),0)) | J52: =INT(ProjStart)+7*4 | K52: =COUNTIFS(Tasks!$I$6:$I$305,">="&J52,Tasks!$I$6:$I$305,"<"&(J52+7)) | L52: =IF(J52>TODAY(),NA(),COUNTIFS(Tasks!$I$6:$I$305,"<"&(J52+7),Tasks!$E$6:$E$305,"Done")) | M52: =COUNTA(Tasks!$B$6:$B$305)
A53: =IF(INDEX(Members,6)="","",INDEX(Members,6)) | B53: =IF(A53="","",COUNTIFS(Tasks!$D$6:$D$305,A53,Tasks!$E$6:$E$305,"<>Done")) | C53: =IF(A53="","",COUNTIFS(Tasks!$D$6:$D$305,A53,Tasks!$E$6:$E$305,"Done")) | D53: =IF(A53="","",COUNTIFS(Tasks!$D$6:$D$305,A53,Tasks!$M$6:$M$305,"Overdue")) | E53: =IF(A53="","",SUMIFS(Tasks!$J$6:$J$305,Tasks!$D$6:$D$305,A53,Tasks!$E$6:$E$305,"<>Done")) | F53: =IF(A53="","",COUNTIFS('Check-ins'!$B$6:$B$505,A53,'Check-ins'!$A$6:$A$505,">="&(TODAY()-6))) | G53: =IF(A53="","",IFERROR(INDEX(Learning!$H$7:$Q$7,MATCH(A53,Learning!$H$5:$Q$5,0)),0)) | J53: =INT(ProjStart)+7*5 | K53: =COUNTIFS(Tasks!$I$6:$I$305,">="&J53,Tasks!$I$6:$I$305,"<"&(J53+7)) | L53: =IF(J53>TODAY(),NA(),COUNTIFS(Tasks!$I$6:$I$305,"<"&(J53+7),Tasks!$E$6:$E$305,"Done")) | M53: =COUNTA(Tasks!$B$6:$B$305)
A54: =IF(INDEX(Members,7)="","",INDEX(Members,7)) | B54: =IF(A54="","",COUNTIFS(Tasks!$D$6:$D$305,A54,Tasks!$E$6:$E$305,"<>Done")) | C54: =IF(A54="","",COUNTIFS(Tasks!$D$6:$D$305,A54,Tasks!$E$6:$E$305,"Done")) | D54: =IF(A54="","",COUNTIFS(Tasks!$D$6:$D$305,A54,Tasks!$M$6:$M$305,"Overdue")) | E54: =IF(A54="","",SUMIFS(Tasks!$J$6:$J$305,Tasks!$D$6:$D$305,A54,Tasks!$E$6:$E$305,"<>Done")) | F54: =IF(A54="","",COUNTIFS('Check-ins'!$B$6:$B$505,A54,'Check-ins'!$A$6:$A$505,">="&(TODAY()-6))) | G54: =IF(A54="","",IFERROR(INDEX(Learning!$H$7:$Q$7,MATCH(A54,Learning!$H$5:$Q$5,0)),0)) | J54: =INT(ProjStart)+7*6 | K54: =COUNTIFS(Tasks!$I$6:$I$305,">="&J54,Tasks!$I$6:$I$305,"<"&(J54+7)) | L54: =IF(J54>TODAY(),NA(),COUNTIFS(Tasks!$I$6:$I$305,"<"&(J54+7),Tasks!$E$6:$E$305,"Done")) | M54: =COUNTA(Tasks!$B$6:$B$305)
A55: =IF(INDEX(Members,8)="","",INDEX(Members,8)) | B55: =IF(A55="","",COUNTIFS(Tasks!$D$6:$D$305,A55,Tasks!$E$6:$E$305,"<>Done")) | C55: =IF(A55="","",COUNTIFS(Tasks!$D$6:$D$305,A55,Tasks!$E$6:$E$305,"Done")) | D55: =IF(A55="","",COUNTIFS(Tasks!$D$6:$D$305,A55,Tasks!$M$6:$M$305,"Overdue")) | E55: =IF(A55="","",SUMIFS(Tasks!$J$6:$J$305,Tasks!$D$6:$D$305,A55,Tasks!$E$6:$E$305,"<>Done")) | F55: =IF(A55="","",COUNTIFS('Check-ins'!$B$6:$B$505,A55,'Check-ins'!$A$6:$A$505,">="&(TODAY()-6))) | G55: =IF(A55="","",IFERROR(INDEX(Learning!$H$7:$Q$7,MATCH(A55,Learning!$H$5:$Q$5,0)),0)) | J55: =INT(ProjStart)+7*7 | K55: =COUNTIFS(Tasks!$I$6:$I$305,">="&J55,Tasks!$I$6:$I$305,"<"&(J55+7)) | L55: =IF(J55>TODAY(),NA(),COUNTIFS(Tasks!$I$6:$I$305,"<"&(J55+7),Tasks!$E$6:$E$305,"Done")) | M55: =COUNTA(Tasks!$B$6:$B$305)
A56: =IF(INDEX(Members,9)="","",INDEX(Members,9)) | B56: =IF(A56="","",COUNTIFS(Tasks!$D$6:$D$305,A56,Tasks!$E$6:$E$305,"<>Done")) | C56: =IF(A56="","",COUNTIFS(Tasks!$D$6:$D$305,A56,Tasks!$E$6:$E$305,"Done")) | D56: =IF(A56="","",COUNTIFS(Tasks!$D$6:$D$305,A56,Tasks!$M$6:$M$305,"Overdue")) | E56: =IF(A56="","",SUMIFS(Tasks!$J$6:$J$305,Tasks!$D$6:$D$305,A56,Tasks!$E$6:$E$305,"<>Done")) | F56: =IF(A56="","",COUNTIFS('Check-ins'!$B$6:$B$505,A56,'Check-ins'!$A$6:$A$505,">="&(TODAY()-6))) | G56: =IF(A56="","",IFERROR(INDEX(Learning!$H$7:$Q$7,MATCH(A56,Learning!$H$5:$Q$5,0)),0)) | J56: =INT(ProjStart)+7*8 | K56: =COUNTIFS(Tasks!$I$6:$I$305,">="&J56,Tasks!$I$6:$I$305,"<"&(J56+7)) | L56: =IF(J56>TODAY(),NA(),COUNTIFS(Tasks!$I$6:$I$305,"<"&(J56+7),Tasks!$E$6:$E$305,"Done")) | M56: =COUNTA(Tasks!$B$6:$B$305)
A57: =IF(INDEX(Members,10)="","",INDEX(Members,10)) | B57: =IF(A57="","",COUNTIFS(Tasks!$D$6:$D$305,A57,Tasks!$E$6:$E$305,"<>Done")) | C57: =IF(A57="","",COUNTIFS(Tasks!$D$6:$D$305,A57,Tasks!$E$6:$E$305,"Done")) | D57: =IF(A57="","",COUNTIFS(Tasks!$D$6:$D$305,A57,Tasks!$M$6:$M$305,"Overdue")) | E57: =IF(A57="","",SUMIFS(Tasks!$J$6:$J$305,Tasks!$D$6:$D$305,A57,Tasks!$E$6:$E$305,"<>Done")) | F57: =IF(A57="","",COUNTIFS('Check-ins'!$B$6:$B$505,A57,'Check-ins'!$A$6:$A$505,">="&(TODAY()-6))) | G57: =IF(A57="","",IFERROR(INDEX(Learning!$H$7:$Q$7,MATCH(A57,Learning!$H$5:$Q$5,0)),0)) | J57: =INT(ProjStart)+7*9 | K57: =COUNTIFS(Tasks!$I$6:$I$305,">="&J57,Tasks!$I$6:$I$305,"<"&(J57+7)) | L57: =IF(J57>TODAY(),NA(),COUNTIFS(Tasks!$I$6:$I$305,"<"&(J57+7),Tasks!$E$6:$E$305,"Done")) | M57: =COUNTA(Tasks!$B$6:$B$305)
J58: =INT(ProjStart)+7*10 | K58: =COUNTIFS(Tasks!$I$6:$I$305,">="&J58,Tasks!$I$6:$I$305,"<"&(J58+7)) | L58: =IF(J58>TODAY(),NA(),COUNTIFS(Tasks!$I$6:$I$305,"<"&(J58+7),Tasks!$E$6:$E$305,"Done")) | M58: =COUNTA(Tasks!$B$6:$B$305)
...

Sheet Settings
A1: Settings
A2: Set up your project here first. Everything else reads from this sheet.
A3: ← Back to Start Here
A5: Project details | F5: Drop-down lists (edit to customise)
A6: Project name | B6: My Project | F6: Task status | G6: Priority | H6: Progress | I6: Learning | J6: Risk status | K6: Mood
A7: Project lead | B7: Your name | F7: Not started | G7: Critical | H7: 0 | I7: Not started | J7: Open | K7: Great
A8: Start date | B8: 46304 | F8: In progress | G8: High | H8: 0.25 | I8: In progress | J8: Monitoring | K8: Good
A9: End date / final deadline | B9: 46360.708 | F9: In review | G9: Medium | H9: 0.5 | I9: Done | J9: Closed | K9: OK
A10: Time zone shown in dates | B10: Local time | F10: Blocked | G10: Low | H10: 0.75 | K10: Struggling
A11: Description | B11: One or two sentences on what this project delivers and for whom. | F11: Done | H11: 1
A14: Team members
A15: Name | B15: Role | C15: Email / contact | D15: GitHub / handle
A16: Alex (example) | B16: Lead
A17: Sam (example) | B17: Member
A18: Jordan (example) | B18: Member | F18: Note: task status 'Done' and 'Blocked' are used by formulas: rename them only together with the formulas.

Sheet Tasks
A1: Tasks
A2: One row per task. Type in the blue cells; grey columns are calculated. Dates: Local time, 12-hour AM/PM.
A3: ← Back to Start Here
A5: ID | B5: Task | C5: Milestone | D5: Owner | E5: Status | F5: Priority | G5: Start | H5: Due | I5: Completed on | J5: Est. hours | K5: Progress | L5: Days left | M5: Health | N5: Depends on | O5: Notes / link | P5: sort key
A6: =IF(B6="","","T-"&TEXT(ROW()-5,"000")) | B6: Example: write the project brief | C6: Planning | D6: Alex (example) | E6: Done | F6: High | G6: 46304 | H6: 46307.708 | I6: 46304 | J6: 3 | K6: 1 | L6: =IF(OR(B6="",H6="",E6="Done"),"",ROUNDDOWN(H6-NOW(),0)) | M6: =IF(B6="","",IF(E6="Done","Complete",IF(E6="Blocked","Blocked",IF(H6="","No due date",IF(H6<NOW(),"Overdue",IF(H6-NOW()<=3,"Due soon","On track")))))) | O6: Example row: overwrite or delete | P6: =IF(OR(B6="",E6="Done",H6=""),"",H6+ROW()/10000000)
A7: =IF(B7="","","T-"&TEXT(ROW()-5,"000")) | B7: Example: set up the shared workspace | C7: Planning | D7: Sam (example) | E7: In progress | F7: Medium | G7: 46304 | H7: 46310.5 | J7: 2 | K7: 0.5 | L7: =IF(OR(B7="",H7="",E7="Done"),"",ROUNDDOWN(H7-NOW(),0)) | M7: =IF(B7="","",IF(E7="Done","Complete",IF(E7="Blocked","Blocked",IF(H7="","No due date",IF(H7<NOW(),"Overdue",IF(H7-NOW()<=3,"Due soon","On track")))))) | O7: Example row | P7: =IF(OR(B7="",E7="Done",H7=""),"",H7+ROW()/10000000)
A8: =IF(B8="","","T-"&TEXT(ROW()-5,"000")) | B8: Example: build the first version | C8: Build | D8: Jordan (example) | E8: Not started | F8: Critical | G8: 46311 | H8: 46334.708 | J8: 20 | K8: 0 | L8: =IF(OR(B8="",H8="",E8="Done"),"",ROUNDDOWN(H8-NOW(),0)) | M8: =IF(B8="","",IF(E8="Done","Complete",IF(E8="Blocked","Blocked",IF(H8="","No due date",IF(H8<NOW(),"Overdue",IF(H8-NOW()<=3,"Due soon","On track")))))) | N8: T-002 | O8: Example row | P8: =IF(OR(B8="",E8="Done",H8=""),"",H8+ROW()/10000000)
A9: =IF(B9="","","T-"&TEXT(ROW()-5,"000")) | L9: =IF(OR(B9="",H9="",E9="Done"),"",ROUNDDOWN(H9-NOW(),0)) | M9: =IF(B9="","",IF(E9="Done","Complete",IF(E9="Blocked","Blocked",IF(H9="","No due date",IF(H9<NOW(),"Overdue",IF(H9-NOW()<=3,"Due soon","On track")))))) | P9: =IF(OR(B9="",E9="Done",H9=""),"",H9+ROW()/10000000)
A10: =IF(B10="","","T-"&TEXT(ROW()-5,"000")) | L10: =IF(OR(B10="",H10="",E10="Done"),"",ROUNDDOWN(H10-NOW(),0)) | M10: =IF(B10="","",IF(E10="Done","Complete",IF(E10="Blocked","Blocked",IF(H10="","No due date",IF(H10<NOW(),"Overdue",IF(H10-NOW()<=3,"Due soon","On track")))))) | P10: =IF(OR(B10="",E10="Done",H10=""),"",H10+ROW()/10000000)
A11: =IF(B11="","","T-"&TEXT(ROW()-5,"000")) | L11: =IF(OR(B11="",H11="",E11="Done"),"",ROUNDDOWN(H11-NOW(),0)) | M11: =IF(B11="","",IF(E11="Done","Complete",IF(E11="Blocked","Blocked",IF(H11="","No due date",IF(H11<NOW(),"Overdue",IF(H11-NOW()<=3,"Due soon","On track")))))) | P11: =IF(OR(B11="",E11="Done",H11=""),"",H11+ROW()/10000000)
A12: =IF(B12="","","T-"&TEXT(ROW()-5,"000")) | L12: =IF(OR(B12="",H12="",E12="Done"),"",ROUNDDOWN(H12-NOW(),0)) | M12: =IF(B12="","",IF(E12="Done","Complete",IF(E12="Blocked","Blocked",IF(H12="","No due date",IF(H12<NOW(),"Overdue",IF(H12-NOW()<=3,"Due soon","On track")))))) | P12: =IF(OR(B12="",E12="Done",H12=""),"",H12+ROW()/10000000)
A13: =IF(B13="","","T-"&TEXT(ROW()-5,"000")) | L13: =IF(OR(B13="",H13="",E13="Done"),"",ROUNDDOWN(H13-NOW(),0)) | M13: =IF(B13="","",IF(E13="Done","Complete",IF(E13="Blocked","Blocked",IF(H13="","No due date",IF(H13<NOW(),"Overdue",IF(H13-NOW()<=3,"Due soon","On track")))))) | P13: =IF(OR(B13="",E13="Done",H13=""),"",H13+ROW()/10000000)
A14: =IF(B14="","","T-"&TEXT(ROW()-5,"000")) | L14: =IF(OR(B14="",H14="",E14="Done"),"",ROUNDDOWN(H14-NOW(),0)) | M14: =IF(B14="","",IF(E14="Done","Complete",IF(E14="Blocked","Blocked",IF(H14="","No due date",IF(H14<NOW(),"Overdue",IF(H14-NOW()<=3,"Due soon","On track")))))) | P14: =IF(OR(B14="",E14="Done",H14=""),"",H14+ROW()/10000000)
A15: =IF(B15="","","T-"&TEXT(ROW()-5,"000")) | L15: =IF(OR(B15="",H15="",E15="Done"),"",ROUNDDOWN(H15-NOW(),0)) | M15: =IF(B15="","",IF(E15="Done","Complete",IF(E15="Blocked","Blocked",IF(H15="","No due date",IF(H15<NOW(),"Overdue",IF(H15-NOW()<=3,"Due soon","On track")))))) | P15: =IF(OR(B15="",E15="Done",H15=""),"",H15+ROW()/10000000)
A16: =IF(B16="","","T-"&TEXT(ROW()-5,"000")) | L16: =IF(OR(B16="",H16="",E16="Done"),"",ROUNDDOWN(H16-NOW(),0)) | M16: =IF(B16="","",IF(E16="Done","Complete",IF(E16="Blocked","Blocked",IF(H16="","No due date",IF(H16<NOW(),"Overdue",IF(H16-NOW()<=3,"Due soon","On track")))))) | P16: =IF(OR(B16="",E16="Done",H16=""),"",H16+ROW()/10000000)
A17: =IF(B17="","","T-"&TEXT(ROW()-5,"000")) | L17: =IF(OR(B17="",H17="",E17="Done"),"",ROUNDDOWN(H17-NOW(),0)) | M17: =IF(B17="","",IF(E17="Done","Complete",IF(E17="Blocked","Blocked",IF(H17="","No due date",IF(H17<NOW(),"Overdue",IF(H17-NOW()<=3,"Due soon","On track")))))) | P17: =IF(OR(B17="",E17="Done",H17=""),"",H17+ROW()/10000000)
A18: =IF(B18="","","T-"&TEXT(ROW()-5,"000")) | L18: =IF(OR(B18="",H18="",E18="Done"),"",ROUNDDOWN(H18-NOW(),0)) | M18: =IF(B18="","",IF(E18="Done","Complete",IF(E18="Blocked","Blocked",IF(H18="","No due date",IF(H18<NOW(),"Overdue",IF(H18-NOW()<=3,"Due soon","On track")))))) | P18: =IF(OR(B18="",E18="Done",H18=""),"",H18+ROW()/10000000)
A19: =IF(B19="","","T-"&TEXT(ROW()-5,"000")) | L19: =IF(OR(B19="",H19="",E19="Done"),"",ROUNDDOWN(H19-NOW(),0)) | M19: =IF(B19="","",IF(E19="Done","Complete",IF(E19="Blocked","Blocked",IF(H19="","No due date",IF(H19<NOW(),"Overdue",IF(H19-NOW()<=3,"Due soon","On track")))))) | P19: =IF(OR(B19="",E19="Done",H19=""),"",H19+ROW()/10000000)
A20: =IF(B20="","","T-"&TEXT(ROW()-5,"000")) | L20: =IF(OR(B20="",H20="",E20="Done"),"",ROUNDDOWN(H20-NOW(),0)) | M20: =IF(B20="","",IF(E20="Done","Complete",IF(E20="Blocked","Blocked",IF(H20="","No due date",IF(H20<NOW(),"Overdue",IF(H20-NOW()<=3,"Due soon","On track")))))) | P20: =IF(OR(B20="",E20="Done",H20=""),"",H20+ROW()/10000000)
... A305: =IF(B305="","","T-"&TEXT(ROW()-5,"000")) | L305: =IF(OR(B305="",H305="",E305="Done"),"",ROUNDDOWN(H305-NOW(),0)) | M305: =IF(B305="","",IF(E305="Done","Complete",IF(E305="Blocked","Blocked",IF(H305="","No due date",IF(H305<NOW(),"Overdue",IF(H305-NOW()<=3,"Due soon","On track")))))) | P305: =IF(OR(B305="",E305="Done",H305=""),"",H305+ROW()/10000000)

Sheet Milestones
A1: Milestones
A2: Big checkpoints or phases. Tasks are linked to a milestone with the Milestone column on the Tasks sheet.
A3: ← Back to Start Here
A5: # | B5: Milestone | C5: Target date | D5: Owner | E5: Tasks | F5: Done | G5: % done | H5: Status | I5: Notes
A6: =IF(B6="","",ROW()-5) | B6: Planning | C6: 46311.708 | E6: =IF(B6="","",COUNTIF(Tasks!$C$6:$C$305,B6)) | F6: =IF(B6="","",COUNTIFS(Tasks!$C$6:$C$305,B6,Tasks!$E$6:$E$305,"Done")) | G6: =IF(OR(B6="",E6=0),"",F6/E6) | H6: =IF(B6="","",IF(AND(E6>0,F6=E6),"Complete",IF(C6="","Planned",IF(C6<NOW(),"Late","On track")))) | I6: Example milestone
A7: =IF(B7="","",ROW()-5) | B7: Build | C7: 46339.708 | E7: =IF(B7="","",COUNTIF(Tasks!$C$6:$C$305,B7)) | F7: =IF(B7="","",COUNTIFS(Tasks!$C$6:$C$305,B7,Tasks!$E$6:$E$305,"Done")) | G7: =IF(OR(B7="",E7=0),"",F7/E7) | H7: =IF(B7="","",IF(AND(E7>0,F7=E7),"Complete",IF(C7="","Planned",IF(C7<NOW(),"Late","On track")))) | I7: Example milestone
A8: =IF(B8="","",ROW()-5) | B8: Launch | C8: 46360.708 | E8: =IF(B8="","",COUNTIF(Tasks!$C$6:$C$305,B8)) | F8: =IF(B8="","",COUNTIFS(Tasks!$C$6:$C$305,B8,Tasks!$E$6:$E$305,"Done")) | G8: =IF(OR(B8="",E8=0),"",F8/E8) | H8: =IF(B8="","",IF(AND(E8>0,F8=E8),"Complete",IF(C8="","Planned",IF(C8<NOW(),"Late","On track")))) | I8: Example milestone
A9: =IF(B9="","",ROW()-5) | E9: =IF(B9="","",COUNTIF(Tasks!$C$6:$C$305,B9)) | F9: =IF(B9="","",COUNTIFS(Tasks!$C$6:$C$305,B9,Tasks!$E$6:$E$305,"Done")) | G9: =IF(OR(B9="",E9=0),"",F9/E9) | H9: =IF(B9="","",IF(AND(E9>0,F9=E9),"Complete",IF(C9="","Planned",IF(C9<NOW(),"Late","On track"))))
A10: =IF(B10="","",ROW()-5) | E10: =IF(B10="","",COUNTIF(Tasks!$C$6:$C$305,B10)) | F10: =IF(B10="","",COUNTIFS(Tasks!$C$6:$C$305,B10,Tasks!$E$6:$E$305,"Done")) | G10: =IF(OR(B10="",E10=0),"",F10/E10) | H10: =IF(B10="","",IF(AND(E10>0,F10=E10),"Complete",IF(C10="","Planned",IF(C10<NOW(),"Late","On track"))))
A11: =IF(B11="","",ROW()-5) | E11: =IF(B11="","",COUNTIF(Tasks!$C$6:$C$305,B11)) | F11: =IF(B11="","",COUNTIFS(Tasks!$C$6:$C$305,B11,Tasks!$E$6:$E$305,"Done")) | G11: =IF(OR(B11="",E11=0),"",F11/E11) | H11: =IF(B11="","",IF(AND(E11>0,F11=E11),"Complete",IF(C11="","Planned",IF(C11<NOW(),"Late","On track"))))
A12: =IF(B12="","",ROW()-5) | E12: =IF(B12="","",COUNTIF(Tasks!$C$6:$C$305,B12)) | F12: =IF(B12="","",COUNTIFS(Tasks!$C$6:$C$305,B12,Tasks!$E$6:$E$305,"Done")) | G12: =IF(OR(B12="",E12=0),"",F12/E12) | H12: =IF(B12="","",IF(AND(E12>0,F12=E12),"Complete",IF(C12="","Planned",IF(C12<NOW(),"Late","On track"))))
A13: =IF(B13="","",ROW()-5) | E13: =IF(B13="","",COUNTIF(Tasks!$C$6:$C$305,B13)) | F13: =IF(B13="","",COUNTIFS(Tasks!$C$6:$C$305,B13,Tasks!$E$6:$E$305,"Done")) | G13: =IF(OR(B13="",E13=0),"",F13/E13) | H13: =IF(B13="","",IF(AND(E13>0,F13=E13),"Complete",IF(C13="","Planned",IF(C13<NOW(),"Late","On track"))))
A14: =IF(B14="","",ROW()-5) | E14: =IF(B14="","",COUNTIF(Tasks!$C$6:$C$305,B14)) | F14: =IF(B14="","",COUNTIFS(Tasks!$C$6:$C$305,B14,Tasks!$E$6:$E$305,"Done")) | G14: =IF(OR(B14="",E14=0),"",F14/E14) | H14: =IF(B14="","",IF(AND(E14>0,F14=E14),"Complete",IF(C14="","Planned",IF(C14<NOW(),"Late","On track"))))
A15: =IF(B15="","",ROW()-5) | E15: =IF(B15="","",COUNTIF(Tasks!$C$6:$C$305,B15)) | F15: =IF(B15="","",COUNTIFS(Tasks!$C$6:$C$305,B15,Tasks!$E$6:$E$305,"Done")) | G15: =IF(OR(B15="",E15=0),"",F15/E15) | H15: =IF(B15="","",IF(AND(E15>0,F15=E15),"Complete",IF(C15="","Planned",IF(C15<NOW(),"Late","On track"))))
A16: =IF(B16="","",ROW()-5) | E16: =IF(B16="","",COUNTIF(Tasks!$C$6:$C$305,B16)) | F16: =IF(B16="","",COUNTIFS(Tasks!$C$6:$C$305,B16,Tasks!$E$6:$E$305,"Done")) | G16: =IF(OR(B16="",E16=0),"",F16/E16) | H16: =IF(B16="","",IF(AND(E16>0,F16=E16),"Complete",IF(C16="","Planned",IF(C16<NOW(),"Late","On track"))))
A17: =IF(B17="","",ROW()-5) | E17: =IF(B17="","",COUNTIF(Tasks!$C$6:$C$305,B17)) | F17: =IF(B17="","",COUNTIFS(Tasks!$C$6:$C$305,B17,Tasks!$E$6:$E$305,"Done")) | G17: =IF(OR(B17="",E17=0),"",F17/E17) | H17: =IF(B17="","",IF(AND(E17>0,F17=E17),"Complete",IF(C17="","Planned",IF(C17<NOW(),"Late","On track"))))
A18: =IF(B18="","",ROW()-5) | E18: =IF(B18="","",COUNTIF(Tasks!$C$6:$C$305,B18)) | F18: =IF(B18="","",COUNTIFS(Tasks!$C$6:$C$305,B18,Tasks!$E$6:$E$305,"Done")) | G18: =IF(OR(B18="",E18=0),"",F18/E18) | H18: =IF(B18="","",IF(AND(E18>0,F18=E18),"Complete",IF(C18="","Planned",IF(C18<NOW(),"Late","On track"))))
A19: =IF(B19="","",ROW()-5) | E19: =IF(B19="","",COUNTIF(Tasks!$C$6:$C$305,B19)) | F19: =IF(B19="","",COUNTIFS(Tasks!$C$6:$C$305,B19,Tasks!$E$6:$E$305,"Done")) | G19: =IF(OR(B19="",E19=0),"",F19/E19) | H19: =IF(B19="","",IF(AND(E19>0,F19=E19),"Complete",IF(C19="","Planned",IF(C19<NOW(),"Late","On track"))))
A20: =IF(B20="","",ROW()-5) | E20: =IF(B20="","",COUNTIF(Tasks!$C$6:$C$305,B20)) | F20: =IF(B20="","",COUNTIFS(Tasks!$C$6:$C$305,B20,Tasks!$E$6:$E$305,"Done")) | G20: =IF(OR(B20="",E20=0),"",F20/E20) | H20: =IF(B20="","",IF(AND(E20>0,F20=E20),"Complete",IF(C20="","Planned",IF(C20<NOW(),"Late","On track"))))
... A35: =IF(B35="","",ROW()-5) | E35: =IF(B35="","",COUNTIF(Tasks!$C$6:$C$305,B35)) | F35: =IF(B35="","",COUNTIFS(Tasks!$C$6:$C$305,B35,Tasks!$E$6:$E$305,"Done")) | G35: =IF(OR(B35="",E35=0),"",F35/E35) | H35: =IF(B35="","",IF(AND(E35>0,F35=E35),"Complete",IF(C35="","Planned",IF(C35<NOW(),"Late","On track"))))

Sheet Timeline
A1: Timeline (Gantt)
A2: Read-only view of the first tasks on the Tasks sheet. Bars run from Start to Due. The gold column is today.
A3: ← Back to Start Here | E3: Show from: | G3: =ProjStart | L3: ← change this date to scroll the timeline
A4: Legend: | B4: Planned | C4: Done | D4: Overdue | E4: Blocked | F4: Today | G4: =IF(OR(1=0,DAY($G$3+1)=1),TEXT($G$3+1,"mmm"),"") | H4: =IF(OR(2=0,DAY($G$3+2)=1),TEXT($G$3+2,"mmm"),"") | I4: =IF(OR(3=0,DAY($G$3+3)=1),TEXT($G$3+3,"mmm"),"") | J4: =IF(OR(4=0,DAY($G$3+4)=1),TEXT($G$3+4,"mmm"),"") | K4: =IF(OR(5=0,DAY($G$3+5)=1),TEXT($G$3+5,"mmm"),"") | L4: =IF(OR(6=0,DAY($G$3+6)=1),TEXT($G$3+6,"mmm"),"") | M4: =IF(OR(7=0,DAY($G$3+7)=1),TEXT($G$3+7,"mmm"),"") | N4: =IF(OR(8=0,DAY($G$3+8)=1),TEXT($G$3+8,"mmm"),"") | O4: =IF(OR(9=0,DAY($G$3+9)=1),TEXT($G$3+9,"mmm"),"") | P4: =IF(OR(10=0,DAY($G$3+10)=1),TEXT($G$3+10,"mmm"),"") | Q4: =IF(OR(11=0,DAY($G$3+11)=1),TEXT($G$3+11,"mmm"),"") | R4: =IF(OR(12=0,DAY($G$3+12)=1),TEXT($G$3+12,"mmm"),"") | S4: =IF(OR(13=0,DAY($G$3+13)=1),TEXT($G$3+13,"mmm"),"") | T4: =IF(OR(14=0,DAY($G$3+14)=1),TEXT($G$3+14,"mmm"),"") | U4: =IF(OR(15=0,DAY($G$3+15)=1),TEXT($G$3+15,"mmm"),"") | V4: =IF(OR(16=0,DAY($G$3+16)=1),TEXT($G$3+16,"mmm"),"") | W4: =IF(OR(17=0,DAY($G$3+17)=1),TEXT($G$3+17,"mmm"),"") | X4: =IF(OR(18=0,DAY($G$3+18)=1),TEXT($G$3+18,"mmm"),"") | Y4: =IF(OR(19=0,DAY($G$3+19)=1),TEXT($G$3+19,"mmm"),"") | Z4: =IF(OR(20=0,DAY($G$3+20)=1),TEXT($G$3+20,"mmm"),"") | AA4: =IF(OR(21=0,DAY($G$3+21)=1),TEXT($G$3+21,"mmm"),"") | AB4: =IF(OR(22=0,DAY($G$3+22)=1),TEXT($G$3+22,"mmm"),"") | AC4: =IF(OR(23=0,DAY($G$3+23)=1),TEXT($G$3+23,"mmm"),"") | AD4: =IF(OR(24=0,DAY($G$3+24)=1),TEXT($G$3+24,"mmm"),"") | AE4: =IF(OR(25=0,DAY($G$3+25)=1),TEXT($G$3+25,"mmm"),"") | AF4: =IF(OR(26=0,DAY($G$3+26)=1),TEXT($G$3+26,"mmm"),"") | AG4: =IF(OR(27=0,DAY($G$3+27)=1),TEXT($G$3+27,"mmm"),"") | AH4: =IF(OR(28=0,DAY($G$3+28)=1),TEXT($G$3+28,"mmm"),"") | AI4: =IF(OR(29=0,DAY($G$3+29)=1),TEXT($G$3+29,"mmm"),"") | AJ4: =IF(OR(30=0,DAY($G$3+30)=1),TEXT($G$3+30,"mmm"),"") | AK4: =IF(OR(31=0,DAY($G$3+31)=1),TEXT($G$3+31,"mmm"),"") | AL4: =IF(OR(32=0,DAY($G$3+32)=1),TEXT($G$3+32,"mmm"),"") | AM4: =IF(OR(33=0,DAY($G$3+33)=1),TEXT($G$3+33,"mmm"),"") | AN4: =IF(OR(34=0,DAY($G$3+34)=1),TEXT($G$3+34,"mmm"),"") | AO4: =IF(OR(35=0,DAY($G$3+35)=1),TEXT($G$3+35,"mmm"),"") | AP4: =IF(OR(36=0,DAY($G$3+36)=1),TEXT($G$3+36,"mmm"),"") | AQ4: =IF(OR(37=0,DAY($G$3+37)=1),TEXT($G$3+37,"mmm"),"") | AR4: =IF(OR(38=0,DAY($G$3+38)=1),TEXT($G$3+38,"mmm"),"") | AS4: =IF(OR(39=0,DAY($G$3+39)=1),TEXT($G$3+39,"mmm"),"") | AT4: =IF(OR(40=0,DAY($G$3+40)=1),TEXT($G$3+40,"mmm"),"") | AU4: =IF(OR(41=0,DAY($G$3+41)=1),TEXT($G$3+41,"mmm"),"") | AV4: =IF(OR(42=0,DAY($G$3+42)=1),TEXT($G$3+42,"mmm"),"") | AW4: =IF(OR(43=0,DAY($G$3+43)=1),TEXT($G$3+43,"mmm"),"") | AX4: =IF(OR(44=0,DAY($G$3+44)=1),TEXT($G$3+44,"mmm"),"") | AY4: =IF(OR(45=0,DAY($G$3+45)=1),TEXT($G$3+45,"mmm"),"") | AZ4: =IF(OR(46=0,DAY($G$3+46)=1),TEXT($G$3+46,"mmm"),"") | BA4: =IF(OR(47=0,DAY($G$3+47)=1),TEXT($G$3+47,"mmm"),"") | BB4: =IF(OR(48=0,DAY($G$3+48)=1),TEXT($G$3+48,"mmm"),"") | BC4: =IF(OR(49=0,DAY($G$3+49)=1),TEXT($G$3+49,"mmm"),"") | BD4: =IF(OR(50=0,DAY($G$3+50)=1),TEXT($G$3+50,"mmm"),"") | BE4: =IF(OR(51=0,DAY($G$3+51)=1),TEXT($G$3+51,"mmm"),"") | BF4: =IF(OR(52=0,DAY($G$3+52)=1),TEXT($G$3+52,"mmm"),"") | BG4: =IF(OR(53=0,DAY($G$3+53)=1),TEXT($G$3+53,"mmm"),"") | BH4: =IF(OR(54=0,DAY($G$3+54)=1),TEXT($G$3+54,"mmm"),"") | BI4: =IF(OR(55=0,DAY($G$3+55)=1),TEXT($G$3+55,"mmm"),"") | BJ4: =IF(OR(56=0,DAY($G$3+56)=1),TEXT($G$3+56,"mmm"),"") | BK4: =IF(OR(57=0,DAY($G$3+57)=1),TEXT($G$3+57,"mmm"),"") | BL4: =IF(OR(58=0,DAY($G$3+58)=1),TEXT($G$3+58,"mmm"),"") | BM4: =IF(OR(59=0,DAY($G$3+59)=1),TEXT($G$3+59,"mmm"),"") | BN4: =IF(OR(60=0,DAY($G$3+60)=1),TEXT($G$3+60,"mmm"),"") | BO4: =IF(OR(61=0,DAY($G$3+61)=1),TEXT($G$3+61,"mmm"),"") | BP4: =IF(OR(62=0,DAY($G$3+62)=1),TEXT($G$3+62,"mmm"),"") | BQ4: =IF(OR(63=0,DAY($G$3+63)=1),TEXT($G$3+63,"mmm"),"") | BR4: =IF(OR(64=0,DAY($G$3+64)=1),TEXT($G$3+64,"mmm"),"") | BS4: =IF(OR(65=0,DAY($G$3+65)=1),TEXT($G$3+65,"mmm"),"") | BT4: =IF(OR(66=0,DAY($G$3+66)=1),TEXT($G$3+66,"mmm"),"") | BU4: =IF(OR(67=0,DAY($G$3+67)=1),TEXT($G$3+67,"mmm"),"") | BV4: =IF(OR(68=0,DAY($G$3+68)=1),TEXT($G$3+68,"mmm"),"") | BW4: =IF(OR(69=0,DAY($G$3+69)=1),TEXT($G$3+69,"mmm"),"") | BX4: =IF(OR(70=0,DAY($G$3+70)=1),TEXT($G$3+70,"mmm"),"") | BY4: =IF(OR(71=0,DAY($G$3+71)=1),TEXT($G$3+71,"mmm"),"") | BZ4: =IF(OR(72=0,DAY($G$3+72)=1),TEXT($G$3+72,"mmm"),"") | CA4: =IF(OR(73=0,DAY($G$3+73)=1),TEXT($G$3+73,"mmm"),"") | CB4: =IF(OR(74=0,DAY($G$3+74)=1),TEXT($G$3+74,"mmm"),"") | CC4: =IF(OR(75=0,DAY($G$3+75)=1),TEXT($G$3+75,"mmm"),"") | CD4: =IF(OR(76=0,DAY($G$3+76)=1),TEXT($G$3+76,"mmm"),"") | CE4: =IF(OR(77=0,DAY($G$3+77)=1),TEXT($G$3+77,"mmm"),"") | CF4: =IF(OR(78=0,DAY($G$3+78)=1),TEXT($G$3+78,"mmm"),"") | CG4: =IF(OR(79=0,DAY($G$3+79)=1),TEXT($G$3+79,"mmm"),"") | CH4: =IF(OR(80=0,DAY($G$3+80)=1),TEXT($G$3+80,"mmm"),"") | CI4: =IF(OR(81=0,DAY($G$3+81)=1),TEXT($G$3+81,"mmm"),"") | CJ4: =IF(OR(82=0,DAY($G$3+82)=1),TEXT($G$3+82,"mmm"),"") | CK4: =IF(OR(83=0,DAY($G$3+83)=1),TEXT($G$3+83,"mmm"),"")
A5: Task | B5: Owner | C5: Status | D5: Start | E5: Due | F5: =$G$3+0 | G5: =$G$3+1 | H5: =$G$3+2 | I5: =$G$3+3 | J5: =$G$3+4 | K5: =$G$3+5 | L5: =$G$3+6 | M5: =$G$3+7 | N5: =$G$3+8 | O5: =$G$3+9 | P5: =$G$3+10 | Q5: =$G$3+11 | R5: =$G$3+12 | S5: =$G$3+13 | T5: =$G$3+14 | U5: =$G$3+15 | V5: =$G$3+16 | W5: =$G$3+17 | X5: =$G$3+18 | Y5: =$G$3+19 | Z5: =$G$3+20 | AA5: =$G$3+21 | AB5: =$G$3+22 | AC5: =$G$3+23 | AD5: =$G$3+24 | AE5: =$G$3+25 | AF5: =$G$3+26 | AG5: =$G$3+27 | AH5: =$G$3+28 | AI5: =$G$3+29 | AJ5: =$G$3+30 | AK5: =$G$3+31 | AL5: =$G$3+32 | AM5: =$G$3+33 | AN5: =$G$3+34 | AO5: =$G$3+35 | AP5: =$G$3+36 | AQ5: =$G$3+37 | AR5: =$G$3+38 | AS5: =$G$3+39 | AT5: =$G$3+40 | AU5: =$G$3+41 | AV5: =$G$3+42 | AW5: =$G$3+43 | AX5: =$G$3+44 | AY5: =$G$3+45 | AZ5: =$G$3+46 | BA5: =$G$3+47 | BB5: =$G$3+48 | BC5: =$G$3+49 | BD5: =$G$3+50 | BE5: =$G$3+51 | BF5: =$G$3+52 | BG5: =$G$3+53 | BH5: =$G$3+54 | BI5: =$G$3+55 | BJ5: =$G$3+56 | BK5: =$G$3+57 | BL5: =$G$3+58 | BM5: =$G$3+59 | BN5: =$G$3+60 | BO5: =$G$3+61 | BP5: =$G$3+62 | BQ5: =$G$3+63 | BR5: =$G$3+64 | BS5: =$G$3+65 | BT5: =$G$3+66 | BU5: =$G$3+67 | BV5: =$G$3+68 | BW5: =$G$3+69 | BX5: =$G$3+70 | BY5: =$G$3+71 | BZ5: =$G$3+72 | CA5: =$G$3+73 | CB5: =$G$3+74 | CC5: =$G$3+75 | CD5: =$G$3+76 | CE5: =$G$3+77 | CF5: =$G$3+78 | CG5: =$G$3+79 | CH5: =$G$3+80 | CI5: =$G$3+81 | CJ5: =$G$3+82 | CK5: =$G$3+83
A6: =IF(Tasks!$B6="","",Tasks!B6) | B6: =IF(Tasks!$B6="","",Tasks!D6) | C6: =IF(Tasks!$B6="","",Tasks!E6) | D6: =IF(Tasks!$B6="","",Tasks!G6) | E6: =IF(Tasks!$B6="","",Tasks!H6)
A7: =IF(Tasks!$B7="","",Tasks!B7) | B7: =IF(Tasks!$B7="","",Tasks!D7) | C7: =IF(Tasks!$B7="","",Tasks!E7) | D7: =IF(Tasks!$B7="","",Tasks!G7) | E7: =IF(Tasks!$B7="","",Tasks!H7)
A8: =IF(Tasks!$B8="","",Tasks!B8) | B8: =IF(Tasks!$B8="","",Tasks!D8) | C8: =IF(Tasks!$B8="","",Tasks!E8) | D8: =IF(Tasks!$B8="","",Tasks!G8) | E8: =IF(Tasks!$B8="","",Tasks!H8)
A9: =IF(Tasks!$B9="","",Tasks!B9) | B9: =IF(Tasks!$B9="","",Tasks!D9) | C9: =IF(Tasks!$B9="","",Tasks!E9) | D9: =IF(Tasks!$B9="","",Tasks!G9) | E9: =IF(Tasks!$B9="","",Tasks!H9)
A10: =IF(Tasks!$B10="","",Tasks!B10) | B10: =IF(Tasks!$B10="","",Tasks!D10) | C10: =IF(Tasks!$B10="","",Tasks!E10) | D10: =IF(Tasks!$B10="","",Tasks!G10) | E10: =IF(Tasks!$B10="","",Tasks!H10)
A11: =IF(Tasks!$B11="","",Tasks!B11) | B11: =IF(Tasks!$B11="","",Tasks!D11) | C11: =IF(Tasks!$B11="","",Tasks!E11) | D11: =IF(Tasks!$B11="","",Tasks!G11) | E11: =IF(Tasks!$B11="","",Tasks!H11)
A12: =IF(Tasks!$B12="","",Tasks!B12) | B12: =IF(Tasks!$B12="","",Tasks!D12) | C12: =IF(Tasks!$B12="","",Tasks!E12) | D12: =IF(Tasks!$B12="","",Tasks!G12) | E12: =IF(Tasks!$B12="","",Tasks!H12)
A13: =IF(Tasks!$B13="","",Tasks!B13) | B13: =IF(Tasks!$B13="","",Tasks!D13) | C13: =IF(Tasks!$B13="","",Tasks!E13) | D13: =IF(Tasks!$B13="","",Tasks!G13) | E13: =IF(Tasks!$B13="","",Tasks!H13)
A14: =IF(Tasks!$B14="","",Tasks!B14) | B14: =IF(Tasks!$B14="","",Tasks!D14) | C14: =IF(Tasks!$B14="","",Tasks!E14) | D14: =IF(Tasks!$B14="","",Tasks!G14) | E14: =IF(Tasks!$B14="","",Tasks!H14)
A15: =IF(Tasks!$B15="","",Tasks!B15) | B15: =IF(Tasks!$B15="","",Tasks!D15) | C15: =IF(Tasks!$B15="","",Tasks!E15) | D15: =IF(Tasks!$B15="","",Tasks!G15) | E15: =IF(Tasks!$B15="","",Tasks!H15)
A16: =IF(Tasks!$B16="","",Tasks!B16) | B16: =IF(Tasks!$B16="","",Tasks!D16) | C16: =IF(Tasks!$B16="","",Tasks!E16) | D16: =IF(Tasks!$B16="","",Tasks!G16) | E16: =IF(Tasks!$B16="","",Tasks!H16)
A17: =IF(Tasks!$B17="","",Tasks!B17) | B17: =IF(Tasks!$B17="","",Tasks!D17) | C17: =IF(Tasks!$B17="","",Tasks!E17) | D17: =IF(Tasks!$B17="","",Tasks!G17) | E17: =IF(Tasks!$B17="","",Tasks!H17)
... A85: =IF(Tasks!$B85="","",Tasks!B85) | B85: =IF(Tasks!$B85="","",Tasks!D85) | C85: =IF(Tasks!$B85="","",Tasks!E85) | D85: =IF(Tasks!$B85="","",Tasks!G85) | E85: =IF(Tasks!$B85="","",Tasks!H85)

Sheet Check-ins
A1: Daily Check-ins
A2: Team progress: one short row per person per day. Anything typed in 'Blocked by' turns red so the lead sees it.
A3: ← Back to Start Here
A5: Date | B5: Member | C5: What I did | D5: What I'll do next | E5: Blocked by | F5: Hours | G5: Mood | H5: Task ID
A6: 46304 | B6: Alex (example) | C6: Wrote the project brief and shared it | D6: Review feedback with the team | E6: — | F6: 2 | G6: Good | H6: T-001

Sheet Learning
A1: Learning Progress
A2: Skills the project needs. Each member marks their own column: Not started → In progress → Done.
A3: ← Back to Start Here
A5: # | B5: Area | C5: Topic | D5: Resource (click) | E5: Est. hours | F5: Team done | G5: Team % | H5: =IF(INDEX(Members,1)="","Member 1",INDEX(Members,1)) | I5: =IF(INDEX(Members,2)="","Member 2",INDEX(Members,2)) | J5: =IF(INDEX(Members,3)="","Member 3",INDEX(Members,3)) | K5: =IF(INDEX(Members,4)="","Member 4",INDEX(Members,4)) | L5: =IF(INDEX(Members,5)="","Member 5",INDEX(Members,5)) | M5: =IF(INDEX(Members,6)="","Member 6",INDEX(Members,6)) | N5: =IF(INDEX(Members,7)="","Member 7",INDEX(Members,7)) | O5: =IF(INDEX(Members,8)="","Member 8",INDEX(Members,8)) | P5: =IF(INDEX(Members,9)="","Member 9",INDEX(Members,9)) | Q5: =IF(INDEX(Members,10)="","Member 10",INDEX(Members,10))
D6: Topics done → | H6: =COUNTIF(H9:H158,"Done") | I6: =COUNTIF(I9:I158,"Done") | J6: =COUNTIF(J9:J158,"Done") | K6: =COUNTIF(K9:K158,"Done") | L6: =COUNTIF(L9:L158,"Done") | M6: =COUNTIF(M9:M158,"Done") | N6: =COUNTIF(N9:N158,"Done") | O6: =COUNTIF(O9:O158,"Done") | ... Q6: =COUNTIF(Q9:Q158,"Done")
D7: % of topics done → | H7: =IFERROR(COUNTIF(H9:H158,"Done")/COUNTA($C$9:$C$158),0) | I7: =IFERROR(COUNTIF(I9:I158,"Done")/COUNTA($C$9:$C$158),0) | J7: =IFERROR(COUNTIF(J9:J158,"Done")/COUNTA($C$9:$C$158),0) | K7: =IFERROR(COUNTIF(K9:K158,"Done")/COUNTA($C$9:$C$158),0) | L7: =IFERROR(COUNTIF(L9:L158,"Done")/COUNTA($C$9:$C$158),0) | M7: =IFERROR(COUNTIF(M9:M158,"Done")/COUNTA($C$9:$C$158),0) | N7: =IFERROR(COUNTIF(N9:N158,"Done")/COUNTA($C$9:$C$158),0) | O7: =IFERROR(COUNTIF(O9:O158,"Done")/COUNTA($C$9:$C$158),0) | ... Q7: =IFERROR(COUNTIF(Q9:Q158,"Done")/COUNTA($C$9:$C$158),0)
D8: Study hours done → | H8: =SUMIF(H9:H158,"Done",$E$9:$E$158) | I8: =SUMIF(I9:I158,"Done",$E$9:$E$158) | J8: =SUMIF(J9:J158,"Done",$E$9:$E$158) | K8: =SUMIF(K9:K158,"Done",$E$9:$E$158) | L8: =SUMIF(L9:L158,"Done",$E$9:$E$158) | M8: =SUMIF(M9:M158,"Done",$E$9:$E$158) | N8: =SUMIF(N9:N158,"Done",$E$9:$E$158) | O8: =SUMIF(O9:O158,"Done",$E$9:$E$158) | ... Q8: =SUMIF(Q9:Q158,"Done",$E$9:$E$158)
A9: =IF(C9="","",ROW()-8) | B9: Example area | C9: Example topic | D9: Example resource (link) | E9: 2 | F9: =IF(C9="","",COUNTIF(H9:Q9,"Done")) | G9: =IF(OR(C9="",COUNTA(Members)=0),"",F9/COUNTA(Members)) | H9: Not started | I9: Not started | J9: Not started
A10: =IF(C10="","",ROW()-8) | F10: =IF(C10="","",COUNTIF(H10:Q10,"Done")) | G10: =IF(OR(C10="",COUNTA(Members)=0),"",F10/COUNTA(Members))
A11: =IF(C11="","",ROW()-8) | F11: =IF(C11="","",COUNTIF(H11:Q11,"Done")) | G11: =IF(OR(C11="",COUNTA(Members)=0),"",F11/COUNTA(Members))
A12: =IF(C12="","",ROW()-8) | F12: =IF(C12="","",COUNTIF(H12:Q12,"Done")) | G12: =IF(OR(C12="",COUNTA(Members)=0),"",F12/COUNTA(Members))
A13: =IF(C13="","",ROW()-8) | F13: =IF(C13="","",COUNTIF(H13:Q13,"Done")) | G13: =IF(OR(C13="",COUNTA(Members)=0),"",F13/COUNTA(Members))
A14: =IF(C14="","",ROW()-8) | F14: =IF(C14="","",COUNTIF(H14:Q14,"Done")) | G14: =IF(OR(C14="",COUNTA(Members)=0),"",F14/COUNTA(Members))
A15: =IF(C15="","",ROW()-8) | F15: =IF(C15="","",COUNTIF(H15:Q15,"Done")) | G15: =IF(OR(C15="",COUNTA(Members)=0),"",F15/COUNTA(Members))
A16: =IF(C16="","",ROW()-8) | F16: =IF(C16="","",COUNTIF(H16:Q16,"Done")) | G16: =IF(OR(C16="",COUNTA(Members)=0),"",F16/COUNTA(Members))
A17: =IF(C17="","",ROW()-8) | F17: =IF(C17="","",COUNTIF(H17:Q17,"Done")) | G17: =IF(OR(C17="",COUNTA(Members)=0),"",F17/COUNTA(Members))
A18: =IF(C18="","",ROW()-8) | F18: =IF(C18="","",COUNTIF(H18:Q18,"Done")) | G18: =IF(OR(C18="",COUNTA(Members)=0),"",F18/COUNTA(Members))
A19: =IF(C19="","",ROW()-8) | F19: =IF(C19="","",COUNTIF(H19:Q19,"Done")) | G19: =IF(OR(C19="",COUNTA(Members)=0),"",F19/COUNTA(Members))
A20: =IF(C20="","",ROW()-8) | F20: =IF(C20="","",COUNTIF(H20:Q20,"Done")) | G20: =IF(OR(C20="",COUNTA(Members)=0),"",F20/COUNTA(Members))
A21: =IF(C21="","",ROW()-8) | F21: =IF(C21="","",COUNTIF(H21:Q21,"Done")) | G21: =IF(OR(C21="",COUNTA(Members)=0),"",F21/COUNTA(Members))
... A158: =IF(C158="","",ROW()-8) | F158: =IF(C158="","",COUNTIF(H158:Q158,"Done")) | G158: =IF(OR(C158="",COUNTA(Members)=0),"",F158/COUNTA(Members))

Sheet Risks & Issues
A1: Risks & Issues
A2: Anything that could go wrong (risk) or already has (issue). Score = likelihood × impact (1–5 each).
A3: ← Back to Start Here
A5: ID | B5: Risk or issue | C5: Type | D5: Likelihood (1-5) | E5: Impact (1-5) | F5: Score | G5: Level | H5: Owner | I5: Mitigation / next step | J5: Status | K5: Review by
A6: =IF(B6="","","R-"&TEXT(ROW()-5,"00")) | B6: Example: key person unavailable near the deadline | C6: Risk | D6: 2 | E6: 4 | F6: =IF(OR(D6="",E6=""),"",D6*E6) | G6: =IF(F6="","",IF(F6>=15,"High",IF(F6>=8,"Medium","Low"))) | H6: Alex (example) | I6: Pair up on every critical task | J6: Open
A7: =IF(B7="","","R-"&TEXT(ROW()-5,"00")) | F7: =IF(OR(D7="",E7=""),"",D7*E7) | G7: =IF(F7="","",IF(F7>=15,"High",IF(F7>=8,"Medium","Low")))
A8: =IF(B8="","","R-"&TEXT(ROW()-5,"00")) | F8: =IF(OR(D8="",E8=""),"",D8*E8) | G8: =IF(F8="","",IF(F8>=15,"High",IF(F8>=8,"Medium","Low")))
A9: =IF(B9="","","R-"&TEXT(ROW()-5,"00")) | F9: =IF(OR(D9="",E9=""),"",D9*E9) | G9: =IF(F9="","",IF(F9>=15,"High",IF(F9>=8,"Medium","Low")))
A10: =IF(B10="","","R-"&TEXT(ROW()-5,"00")) | F10: =IF(OR(D10="",E10=""),"",D10*E10) | G10: =IF(F10="","",IF(F10>=15,"High",IF(F10>=8,"Medium","Low")))
A11: =IF(B11="","","R-"&TEXT(ROW()-5,"00")) | F11: =IF(OR(D11="",E11=""),"",D11*E11) | G11: =IF(F11="","",IF(F11>=15,"High",IF(F11>=8,"Medium","Low")))
A12: =IF(B12="","","R-"&TEXT(ROW()-5,"00")) | F12: =IF(OR(D12="",E12=""),"",D12*E12) | G12: =IF(F12="","",IF(F12>=15,"High",IF(F12>=8,"Medium","Low")))
A13: =IF(B13="","","R-"&TEXT(ROW()-5,"00")) | F13: =IF(OR(D13="",E13=""),"",D13*E13) | G13: =IF(F13="","",IF(F13>=15,"High",IF(F13>=8,"Medium","Low")))
A14: =IF(B14="","","R-"&TEXT(ROW()-5,"00")) | F14: =IF(OR(D14="",E14=""),"",D14*E14) | G14: =IF(F14="","",IF(F14>=15,"High",IF(F14>=8,"Medium","Low")))
A15: =IF(B15="","","R-"&TEXT(ROW()-5,"00")) | F15: =IF(OR(D15="",E15=""),"",D15*E15) | G15: =IF(F15="","",IF(F15>=15,"High",IF(F15>=8,"Medium","Low")))
A16: =IF(B16="","","R-"&TEXT(ROW()-5,"00")) | F16: =IF(OR(D16="",E16=""),"",D16*E16) | G16: =IF(F16="","",IF(F16>=15,"High",IF(F16>=8,"Medium","Low")))
A17: =IF(B17="","","R-"&TEXT(ROW()-5,"00")) | F17: =IF(OR(D17="",E17=""),"",D17*E17) | G17: =IF(F17="","",IF(F17>=15,"High",IF(F17>=8,"Medium","Low")))
A18: =IF(B18="","","R-"&TEXT(ROW()-5,"00")) | F18: =IF(OR(D18="",E18=""),"",D18*E18) | G18: =IF(F18="","",IF(F18>=15,"High",IF(F18>=8,"Medium","Low")))
... A105: =IF(B105="","","R-"&TEXT(ROW()-5,"00")) | F105: =IF(OR(D105="",E105=""),"",D105*E105) | G105: =IF(F105="","",IF(F105>=15,"High",IF(F105>=8,"Medium","Low")))
